Workbook

Sheet IZIN BONGKAR
A7: Nomor | C7: : | I7: Kepada
A8: Lampiran | C8: : | I8: Yth. Kepala Kantor Unit Penyelenggara Pelabuhan Kelas III Pelabuhan Marapokot
A9: Perihal | C9: : | D9: Permohonan Ijin Bongkar
I11: Di-
I13: Marapokot
A15: Dengan hormat,
A16: Dengan ini kami datang kehadapan bapak dan mengajukan permohonan kiranya bapak tidak keberatan memberikan ijin bongkar untuk kapal kami tersebut dibawah ini :
B18: Nama kapal | E18: : | F18: …………….(Nama kapal)
B19: Bendera | E19: : | F19: …………………… (Indonesia/negara luar)
B20: Isi kotor | E20: : | F20: GT. ………………… (isi angka)
B21: Nakhoda | E21: : | F21: ………………………. ( Nama kapten Kapal)
B22: ABK | E22: : | F22: ……………. (jumlah ) orang
B23: Tiba tanggal | E23: : | F23: …………………………. (dd/mmmm/yyyy)
B24: Dari pelabuhan | E24: : | F24: ……………………………… (nama pelabuhan)
B25: Bongkaran | E25: : | F25: …………………… (Jumlah) Ton/M3
A27: Kegiatan bongkar muat ……………. (Nma barang) milik ………………………. (nama badan usaha/perorangan) direncanakan akan dilaksanakan kegiatannya pada tanggal …………….. (dd/mmmm/yyyy).
P29: 100000
A30: Demikian surat permohonan ini kami sampaikan dan atas pertimbangan bapak memberikan ijin bongkar kami ucapkan banyak terima kasih.
I35: Maraokot, …………………………………….
I37: PERUSAHAAN BONGKAR MUAT
I38: PT. EMKA JAYA UTAMA
I44: HILARIUS MBUSA
I45: DIREKTUR

Sheet IZIN MENGELUARKAN BARANG
A8: Nomor | C8: : | I8: Kepada
A9: Lampiran | C9: : | I9: Yth. Kepala Kantor Unit Penyelenggara Pelabuhan Kelas III Pelabuhan Marapokot
A10: Perihal | C10: : | D10: Permohonan Ijin Mengeluarkan Barang
I12: Di-
I14: Marapokot
A16: Dengan hormat,
A17: Dengan ini kami ……………………….. (nama perusahaan) bermaksud mengajukan permhonan untuk dapat melaksanakan proses pengeluaran barang kami pada kapal tersebut dibawah ini :
B19: Nama kapal | E19: : | F19: …………….(Nama kapal)
B20: Bendera | E20: : | F20: …………………… (Indonesia/negara luar)
B21: Isi kotor | E21: : | F21: GT. ………………… (isi angka)
B22: Nakhoda | E22: : | F22: ………………………. ( Nama kapten Kapal)
B23: ABK | E23: : | F23: ……………. (jumlah ) orang
B24: Tiba tanggal | E24: : | F24: …………………………. (dd/mmmm/yyyy)
B25: Dari pelabuhan | E25: : | F25: ……………………………… (nama pelabuhan)
B26: Bongkaran | E26: : | F26: …………………… (Jumlah) Ton/M3
A28: Kegiatan bongkar muat ……………. (Nma barang) milik ………………………. (nama badan usaha/perorangan) direncanakan akan dilaksanakan kegiatannya pada tanggal …………….. (dd/mmmm/yyyy).
A31: Demikian surat permohonan ini kami sampaikan dan atas pertimbangan bapak memberikan ijin bongkar kami ucapkan banyak terima kasih.
H36: Maraokot, …………………………………….
H38: PERUSAHAAN JASA PENGURUSAN TRANSPORTASI
H39: PT. EMKA JAYA UTAMA
H45: HILARIUS MBUSA
H46: DIREKTUR

Sheet IZIN PEMASUKAN BARANG
A8: Nomor | C8: : | D8: 005/PT.EMKA/NGK/03/2025 | I8: Kepada
A9: Lampiran | C9: : | D9: - | I9: Yth. Kepala Kantor Unit Penyelenggara Pelabuhan Kelas III Pelabuhan Marapokot
A10: Perihal | C10: : | D10: Permohonan Ijin Pemasukan Barang
I12: Di-
I14: Marapokot
A16: Dengan hormat,
A17: Dengan ini kami PT. EMKA JAYA UTAMA bermaksud mengajukan permhonan untuk dapat melaksanakan proses pemasukan barang kami ke lapangan penumpukan sebagai berikut ::
B19: Nama Barang | E19: :
B20: Volume | E20: :
B21: Asal Barang | E21: :
B22: Tempat penumpukan | E22: :
B23: Tanggal mulai | E23: :
B24: Tanggal Selesai | E24: :
A26: Kegiatan Pemasukan Pasir Besi milik PT.LISINDO SANTOSA direncanakan akan dilaksanakan kegiatannya pada tanggal 19 Maret 2025.
A29: Demikian surat permohonan ini kami sampaikan dan atas pertimbangan bapak memberikan ijin pemasukan barang kami ucapkan banyak terima kasih.
G33: Maraokot, 18 Maret 2025
G35: PERUSAHAAN JASA PENGURUSAN TRANSPORTASI
G36: PT. EMKA JAYA UTAMA
G40: HILARIUS MBUSA
G41: DIREKTUR
A45: Tembusan disampaikan dengan hormat :
A46: 1. Kepala KP3 Laut Pelabuhan Marapokot | I46: di Marapokor
A47: 2. Pemilik barang PT/CV. …………….. | I47: di Sesuaikan
A48: 3. Arsip

Sheet IZIN PENUMPUKAN
A8: Nomor | C8: : | D8: 006/PT.EMKA/NGK/03/2025 | I8: Kepada
A9: Lampiran | C9: : | D9: - | I9: Yth. Kepala Kantor Unit Penyelenggara Pelabuhan Kelas III Pelabuhan Marapokot
A10: Perihal | C10: : | D10: Permohonan Ijin Pemasukan Barang
I12: Di-
I14: Marapokot
A16: Dengan hormat,
A17: Dengan ini kami PT. EMKA JAYA UTAMA bermaksud mengajukan permhonan untuk dapat melaksanakan proses pemasukan barang kami ke lapangan penumpukan sebagai berikut ::
B19: Nama Barang | E19: :
B20: Volume | E20: :
B21: Asal Barang | E21: :
B22: Tempat penumpukan | E22: :
B23: Tanggal mulai | E23: :
B24: Tanggal Selesai | E24: :
A26: Kegiatan Pemasukan Pasir Besi milik PT.LISINDO SANTOSA direncanakan akan dilaksanakan kegiatannya pada tanggal 19 Maret 2025.
A29: Demikian surat permohonan ini kami sampaikan dan atas pertimbangan bapak memberikan ijin penumpukan barang kami ucapkan banyak terima kasih.
G34: Maraokot, 18 Maret 2025
G36: PERUSAHAAN JASA PENGURUSAN TRANSPORTASI
G37: PT. EMKA JAYA UTAMA
G43: HILARIUS MBUSA
G44: DIREKTUR
A48: Tembusan disampaikan dengan hormat :
A49: 1. Kepala KP3 Laut Pelabuhan Marapokot | I49: di Marapokor
A50: 2. Arsip

Sheet IZIN T4 PENUMPUKAN
A8: Nomor | C8: : | D8: 007/PT.EMKA/NGK/03/2025
A9: Lampiran | C9: : | D9: -
A10: Perihal | C10: : | D10: Permohonan Tempat Penumpukan Material
C13: Kepada
C14: Yth. Kepala Kantor Unit Penyelenggara Pelabuhan Kelas III Pelabuhan Marapokot
C18: Di-
C20: Marapokot
C22: Dengan hormat,
C23: Sehubungan dengan perihal surat di atas dan memperhatikan Peraturan Menteri Perhubungan Nomor : 152 Tahun 2016 tentang Penyelenggaaraan dan Pengurusan Bongkar Muat Barang dari dan ke Kapal, dengan ini kami mengajukan permohonan Tempat Penumpukan Material. Adapun material yang akan kami kirim ke tempat penumpukan adalah berupa Biji Besi.
C29: Demikian permohonan kami, bilamana disetujui kami menyatakan bersedia memenuhi semua ketentuan peraturan perundang-undangan yang berlaku.
G33: Maraokot, 18 Maret 2025
G35: PERUSAHAAN JASA PENGURUSAN TRANSPORTASI
G36: PT. EMKA JAYA UTAMA
G42: HILARIUS MBUSA
G43: DIREKTUR

Sheet BA  PENUMPUKAN
A7: BERITA ACARA SERAH TERIMA BARANG
A8: NOMOR : 020/PT.EMKA/NGK/09/2025
A10: pada hari ini Selasa tanggal Dua Puluh Sembilan Bulan September Tahun Dua Ribu Dua Puluh Empat kami yang bertanda tangan dibawah ini masing-masing :
A12: I. | B12: Nama Perusahaan | F12: : | G12: PT. LISINDO SANTOSA | O12: PT. Lisindo Santosa
B13: Alamat | F13: : | G13: Jalan Dukuh Kupang Barat 1B No. 5 - Surabaya
B14: Diwakili oleh | F14: : | G14: ……………………………
B15: Jabatan | F15: : | G15: ……………………………
B16: Dalam hal ini bertindak atas nama PT. LISINDO SANTOSA berkedudukan di Jalan Dukuh Kupang Barat 1B No. 5 - Surabaya yang selanjutnya disebut PIHAK PERTAMA
A18: II. | B18: Nama Perusahaan | F18: : | G18: PT. EMKA JAYA UTAMA
B19: Alamat | F19: : | G19: Depan Polsek Mauponggo, Kel. Mauponggo, Kec. Mauponggo, Kab. Nagekeo, Provinsi Nusa Tenggara Timur (86463)
B21: Diwakili oleh | F21: : | G21: Hilarius Mbusa
B22: Jabatan | F22: : | G22: Direktur
B23: Dalam hal ini bertindak atas nama PT. EMKA JAYA UTAMA berkedudukan di Jl. Trans Danga-Aemalai, Desa Nggolombay, Kecamatan Aesesa, kabupaten Nagekeo Provinsi Nusa Tenggara Timur yang selanjutnya disebut PIHAK KEDUA
A27: Dengan ini menyatakan bahwa PIHAK PERTAMA telah menyerahkan barang milik PT. LISINDO SANTOSA kepada PIHAK KEDUA dan PIHAK KEDUA telah menerima barang tersebut dari PIHAK PERTAMA dengan keterangan dan rincian sebagai berikut :
B30: 1. | C30: Nama Barang | F30: : | G30: ='IZIN PENUMPUKAN'!F19 -> 0
B31: 2. | C31: Volume | F31: : | G31: 1600 Ton
B32: 3. | C32: Asal barang | F32: : | G32: Desa Nggolonio
B33: 4. | C33: Tempat penumpukan | F33: : | G33: PelataranPelabuhan Marapokot
B34: 5. | C34: Tanggal muat | F34: : | G34: ……………………………….
B35: 6. | C35: Tanggal selesai | F35: : | G35: ……………………………….
C36: 7.1. | D36: Hasil Pemasukan/Penumpukan
D37: - | E37: Jumlah Retase | F37: : | G37: 209 | H37: Reit | I37: = | J37: =G37 -> 209 | K37: Reit
D38: - | E38: Total Muatan | F38: : | G38: 1600 | H38: Ton | I38: = | J38: =G38 -> 1600 | K38: Ton
D39: - | E39: Sweeping | F39: : | H39: Ton | I39: = | K39: Ton
E40: Jumlah | F40: : | G40: =G38 -> 1600 | H40: Ton | I40: = | J40: =J38 -> 1600 | K40: Ton
D41: - | E41: Short landed | F41: : | G41: 0 | H41: Ton | I41: = | J41: 0 | K41: Ton
D42: - | E42: Susut | F42: : | G42: 0 | H42: Ton | I42: = | J42: 0 | K42: Ton
E43: Total sesuai B/L | G43: =G40 -> 1600 | H43: Ton | I43: = | J43: =J40 -> 1600 | K43: Ton
A45: Demikian Berita Acara Serah Terima Barang ini dibuat dengan sebenarnya agar yang bersangkutan / berkepentingan menjadi maklum
A48: Yang Menerima, | I48: Yang Menyerahkan
A49: =G12 -> PT. LISINDO SANTOSA | I49: Perusahaan Jasa Pengurusan Tarnsportasi
I50: =G18 -> PT. EMKA JAYA UTAMA
A55: =UPPER(G14) -> …………………………… | I55: =UPPER(G21) -> HILARIUS MBUSA
A56: =G15 -> …………………………… | I56: =G22 -> Direktur

Sheet BA  PENGELUARAN
A7: BERITA ACARA SERAH TERIMA BARANG
A8: NOMOR : 020/PT.EMKA/NGK/09/2025
A10: pada hari ini Selasa tanggal Dua Puluh Sembilan Bulan September Tahun Dua Ribu Dua Puluh Empat kami yang bertanda tangan dibawah ini masing-masing :
A12: I. | B12: Nama Perusahaan | F12: : | G12: PT. LISINDO SANTOSA | O12: PT. Lisindo Santosa
B13: Alamat | F13: : | G13: Jalan Dukuh Kupang Barat 1B No. 5 - Surabaya
B14: Diwakili oleh | F14: : | G14: ……………………………
B15: Jabatan | F15: : | G15: ……………………………
B16: Dalam hal ini bertindak atas nama PT. LISINDO SANTOSA berkedudukan di Jalan Dukuh Kupang Barat 1B No. 5 - Surabaya yang selanjutnya disebut PIHAK PERTAMA
A18: II. | B18: Nama Perusahaan | F18: : | G18: PT. EMKA JAYA UTAMA
B19: Alamat | F19: : | G19: Depan Polsek Mauponggo, Kel. Mauponggo, Kec. Mauponggo, Kab. Nagekeo, Provinsi Nusa Tenggara Timur (86463)
B21: Diwakili oleh | F21: : | G21: Hilarius Mbusa
B22: Jabatan | F22: : | G22: Direktur
B23: Dalam hal ini bertindak atas nama PT. EMKA JAYA UTAMA berkedudukan di Jl. Trans Danga-Aemalai, Desa Nggolombay, Kecamatan Aesesa, kabupaten Nagekeo Provinsi Nusa Tenggara Timur yang selanjutnya disebut PIHAK KEDUA
A27: Dengan ini menyatakan bahwa PIHAK PERTAMA telah menyerahkan barang milik PT. LISINDO SANTOSA kepada PIHAK KEDUA dan PIHAK KEDUA telah menerima barang tersebut dari PIHAK PERTAMA dengan keterangan dan rincian sebagai berikut :
B30: 1. | C30: Nama kapal | F30: : | G30: ……………………………….
B31: 2. | C31: Jenis barang | F31: : | G31: ……………………………….
B32: 3. | C32: Jumlah barang | F32: : | G32: ……………………………….
B33: 4. | C33: Pelabuhan muat/asal | F33: : | G33: ……………………………….
B34: 5. | C34: Pelabuhan tujuan | F34: : | G34: ……………………………….
B35: 6. | C35: Periode bongkaran | F35: : | G35: ……………………………….
C36: 6.1. | D36: Tanggal mulai | F36: : | G36: ……………………………….
C37: 6.2. | D37: Tanggal selesai | F37: : | G37: ……………………………….
B38: 7. | C38: Jumlah yang diserahkan
C39: 7.1. | D39: Hasil Pengeluaran barang
D40: - | E40: Jumlah Retase | F40: : | G40: 0 | H40: Reit | I40: = | J40: =G40 -> 0 | K40: Reit
D41: - | E41: Total Muatan | F41: : | G41: 0 | H41: Ton | I41: = | J41: =G41 -> 0 | K41: Ton
D42: - | E42: Sweeping | F42: : | H42: Ton | I42: = | K42: Ton
E43: Jumlah | F43: : | G43: =G41 -> 0 | H43: Ton | I43: = | J43: =J41 -> 0 | K43: Ton
D44: - | E44: Short landed | F44: : | G44: 0 | H44: Ton | I44: = | J44: 0 | K44: Ton
D45: - | E45: Susut | F45: : | G45: 0 | H45: Ton | I45: = | J45: 0 | K45: Ton
E46: Total sesuai B/L | G46: =G43 -> 0 | H46: Ton | I46: = | J46: =J43 -> 0 | K46: Ton
A48: Demikian Berita Acara Serah Terima Barang ini dibuat dengan sebenarnya agar yang bersangkutan / berkepentingan menjadi maklum
A51: Yang Menerima, | I51: Yang Menyerahkan
A52: =G12 -> PT. LISINDO SANTOSA | I52: Perusahaan Jasa Pengurusan Tarnsportasi
I53: =G18 -> PT. EMKA JAYA UTAMA
A57: =UPPER(G14) -> …………………………… | I57: =UPPER(G21) -> HILARIUS MBUSA
A58: =G15 -> …………………………… | I58: =G22 -> Direktur

Sheet BA BONGKA MUAT
A7: BERITA ACARA SERAH TERIMA BARANG
A8: NOMOR : ………………………………….
A10: pada hari ini …………………..tanggal ………………….. Bulan …………………. Tahun ……………………………………….., kami yang bertanda tangan dibawah ini masing-masing :
A12: I. | B12: Nama Perusahaan | F12: : | G12: ……………………………
B13: Alamat | F13: : | G13: ……………………………
B14: Diwakili oleh | F14: : | G14: ……………………………
B15: Jabatan | F15: : | G15: ……………………………
B16: Dalam hal ini bertindak atas nama ………………………………………. (nama perusahaan ) berkedudukan di ……………………………………………. (alamat perusahaan)yang selanjutnya disebut PIHAK PERTAMA
A19: II. | B19: Nama Perusahaan | F19: : | G19: PT. EMKA JAYA UTAMA
B20: Alamat | F20: : | G20: Depan Polsek Mauponggo, Kel. Mauponggo, Kec. Mauponggo, Kab. Nagekeo, Provinsi Nusa Tenggara Timur (86463)
B22: Diwakili oleh | F22: : | G22: Hilarius Mbusa
B23: Jabatan | F23: : | G23: Direktur
B24: Dalam hal ini bertindak atas nama PT. EMKA JAYA UTAMA berkedudukan di Jl. Trans Danga-Aemalai, Desa Nggolombay, Kecamatan Aesesa, kabupaten Nagekeo Provinsi Nusa Tenggara Timur yang selanjutnya disebut PIHAK KEDUA
P27: =2000/25 -> 80
A28: Dengan ini menyatakan bahwa PIHAK PERTAMA telah menyerahkan barang milik ………………………(pemilik barang perorangan ataupun badan usaha)kepada PIHAK KEDUA dan PIHAK KEDUA telah menerima barang tersebut dari PIHAK PERTAMA dengan keterangan dan rincian sebagai berikut :
B31: 1. | C31: Nama kapal
B32: 2. | C32: Jenis barang
B33: 3. | C33: Jumlah barang
B34: 4. | C34: Pelabuhan muat/asal
B35: 5. | C35: Pelabuhan tujuan
B36: 6. | C36: Periode bongkaran
B37: 7. | C37: Jumlah yang diserahkan
C38: 7.1. | D38: Hasil Bongkaran
D39: - | E39: Original / utuh | F39: : | G39: 98800 | H39: Zak | I39: = | J39: =G39/25 -> 3952 | K39: Ton
D40: - | E40: Original / beku | F40: : | G40: 0 | H40: Zak | I40: = | J40: =G40/25 -> 0 | K40: Ton
D41: - | E41: Pecah / robek | F41: : | G41: 1200 | H41: Zak | I41: = | J41: =G41/25 -> 48 | K41: Ton
E42: Jumlah | F42: : | G42: =SUM(G39:G41) -> 100000 | H42: Zak | I42: = | J42: =SUM(J39:J41) -> 4000 | K42: Ton | O42: =G39-G41 -> 97600
D43: - | E43: Short landed | F43: : | G43: 0 | H43: Zak | I43: = | J43: 0 | K43: Ton
D44: - | E44: Susut | F44: : | G44: 0 | H44: Zak | I44: = | J44: 0 | K44: Ton
E45: Total sesuai B/L | G45: =SUM(G43:G44) -> 0 | H45: Zak | I45: = | J45: =SUM(J43:J44) -> 0 | K45: Ton
C47: 7.2. | D47: Spare bags
D48: - | E48: Jumlah menurun B/L | I48: = | J48: 0 | K48: Lembar
D49: - | E49: Jumlah yang diserahkan | I49: = | J49: 250 | K49: Lembar
A57: Demikian Berita Acara Serah Terima Barang ini dibuat dengan sebenarnya agar yang bersangkutan / berkepentingan menjadi maklum
A60: Yang Menerima, | I60: Yang Menyerahkan
A61: Perusahaan Bongkar Muat
A62: =G19 -> PT. EMKA JAYA UTAMA | I62: =G12 -> ……………………………
A68: =UPPER(G22) -> HILARIUS MBUSA | I68: =UPPER(G14) -> ……………………………
A69: =G23 -> Direktur | I69: =G15 -> ……………………………
A71: Mengetahui,
...

Sheet BA JPT
A7: BERITA ACARA SERAH TERIMA BARANG
A8: NOMOR : ………………………………….
A10: pada hari ini …………………..tanggal ………………….. Bulan …………………. Tahun ……………………………………….., kami yang bertanda tangan dibawah ini masing-masing :
A12: I. | B12: Nama Perusahaan | F12: : | G12: ……………………………
B13: Alamat | F13: : | G13: ……………………………
B14: Diwakili oleh | F14: : | G14: ……………………………
B15: Jabatan | F15: : | G15: ……………………………
B16: Dalam hal ini bertindak atas nama ………………………………………. (nama perusahaan ) berkedudukan di ……………………………………………. (alamat perusahaan)yang selanjutnya disebut PIHAK PERTAMA
A19: II. | B19: Nama Perusahaan | F19: : | G19: PT. EMKA JAYA UTAMA
B20: Alamat | F20: : | G20: Depan Polsek Mauponggo, Kel. Mauponggo, Kec. Mauponggo, Kab. Nagekeo, Provinsi Nusa Tenggara Timur (86463)
B22: Diwakili oleh | F22: : | G22: Hilarius Mbusa
B23: Jabatan | F23: : | G23: Direktur
B24: Dalam hal ini bertindak atas nama PT. EMKA JAYA UTAMA berkedudukan di Jl. Trans Danga-Aemalai, Desa Nggolombay, Kecamatan Aesesa, kabupaten Nagekeo Provinsi Nusa Tenggara Timur yang selanjutnya disebut PIHAK KEDUA
A28: Dengan ini menyatakan bahwa PIHAK PERTAMA telah menyerahkan barang milik ………………………(pemilik barang perorangan ataupun badan usaha)kepada PIHAK KEDUA dan PIHAK KEDUA telah menerima barang tersebut dari PIHAK PERTAMA dengan keterangan dan rincian sebagai berikut :
B31: 1. | C31: Nama kapal
B32: 2. | C32: Jenis barang
B33: 3. | C33: Jumlah barang
B34: 4. | C34: Pelabuhan muat/asal
B35: 5. | C35: Pelabuhan tujuan
B36: 6. | C36: Periode bongkaran
B37: 7. | C37: Jumlah yang diserahkan
C38: 7.1. | D38: Hasil Bongkaran
D39: - | E39: Original / utuh | F39: : | G39: =50000-G41 -> 48500 | H39: Zak | I39: = | J39: =G39/25 -> 1940 | K39: Ton
D40: - | E40: Original / beku | F40: : | G40: 0 | H40: Zak | I40: = | J40: =G40/25 -> 0 | K40: Ton
D41: - | E41: Pecah / robek | F41: : | G41: 1500 | H41: Zak | I41: = | J41: =G41/25 -> 60 | K41: Ton
D42: - | E42: Sweeping | F42: : | H42: Zak | I42: = | K42: Ton
E43: Jumlah | F43: : | G43: =SUM(G39:G42) -> 50000 | H43: Zak | I43: = | J43: =SUM(J39:J42) -> 2000 | K43: Ton
D44: - | E44: Short landed | F44: : | G44: 0 | H44: Zak | I44: = | J44: 0 | K44: Ton
D45: - | E45: Susut | F45: : | G45: 0 | H45: Zak | I45: = | J45: 0 | K45: Ton
E46: Total sesuai B/L | G46: =SUM(G44:G45) -> 0 | H46: Zak | I46: = | J46: =SUM(J44:J45) -> 0 | K46: Ton
C48: 7.2. | D48: Spare bags
D49: - | E49: Jumlah menurun B/L | I49: = | J49: 0 | K49: Lembar
D50: - | E50: Jumlah yang diserahkan | I50: = | J50: 250 | K50: Lembar
A58: Demikian Berita Acara Serah Terima Barang ini dibuat dengan sebenarnya agar yang bersangkutan / berkepentingan menjadi maklum
A61: Yang Menerima, | I61: Yang Menyerahkan
A62: =G12 -> …………………………… | I62: Perusahaan Jasa Pengurusan Tarnsportasi
I63: =G19 -> PT. EMKA JAYA UTAMA
A68: =UPPER(G14) -> …………………………… | I68: =UPPER(G22) -> HILARIUS MBUSA
A69: =G15 -> …………………………… | I69: =G23 -> Direktur

Sheet TIME SHEET
N4: 1500
N5: 25
N6: =N4/N5 -> 60
A8: T I M E S H E E T
A10: Nama Kapal | C10: :
A11: DWT | C11: :
A12: Tanggal tiba | C12: :
A13: Jumlah dan Jenis Muatan | C13: :
A14: Pelabuhan muatan | C14: :
A15: Penerima barang | C15: :
A17: Hari/Tanggal | C17: Cuaca | E17: Mulai Kerja Pukul | G17: Palka | H17: Akhir Kerja Pukul | J17: Hasil Bongkaran
J18: Zak | K18: Ton
A19: 1 | C19: =A19+1 -> 2 | E19: =C19+1 -> 3 | G19: =E19+1 -> 4 | H19: =G19+1 -> 5 | J19: =H19+1 -> 6 | K19: =J19+1 -> 7
G33: Marapokot, 11 September 2023
G35: Perusahaan Bongkar muat dan Jasa Pengurusan Transportasi
G37: ='BA JPT'!I63 -> PT. EMKA JAYA UTAMA
G44: ='BA JPT'!I68 -> HILARIUS MBUSA
G45: ='BA JPT'!I69 -> Direktur

Sheet SURAT JALAN
A3: ='TIME SHEET'!G37 -> PT. EMKA JAYA UTAMA | G3: SURAT JALAN
A4: ='BA BONGKA MUAT'!G20 -> Depan Polsek Mauponggo, Kel. Mauponggo, Kec. Mauponggo, Kab. Nagekeo, Provinsi Nusa Tenggara Timur (86463)
G5: Nomor surat jalan | J5: : | K5: ………………………………
G6: Tanggal | J6: : | K6: ………………………………
G7: Berangkat pukul | J7: : | K7: ………………………………
A8: Kepada : | G8: Dikirim dengan | J8: : | K8: ………………………………
G9: No. Polisi | J9: : | K9: ………………………………
G10: Nama Pengemudi | J10: : | K10: ………………………………
A13: No. | B13: Kode Barang | C13: Nama barang | G13: Jumlah Barang | I13: Keterangan
G14: Zak | H14: Ton
A15: 1 | B15: 2 | C15: 3 | G15: 4 | H15: 5 | I15: 6
A25: Tanda terima | E25: Sopir | H25: Teli kapal | K25: Teli gudang
A30: (…………………………………..)
A33: Catatan :

Sheet SURAT JALAN (2)
A2: S U R A T J A L A N
A4: PT. EMKA JAYA UTAMA
A5: Depan Polsek Mauponggo, Kel. Mauponggo | F5: Nomor surat jalan | I5: :
A6: Kec. Mauponggo, Kab. Nagekeo, | F6: Tanggal | I6: :
A7: Prov. NTT (86463) | F7: Berangkat pukul | I7: :
F8: Dikirim dengan | I8: :
F9: No. Polisi | I9: :
F10: Nama Pengemudi | I10: :
A12: No. | B12: Kode Barang | C12: Nama barang | G12: Jumlah Barang | I12: Keterangan
G13: Zak | H13: Ton
A14: 1 | B14: 2 | C14: 3 | G14: 4 | H14: 5 | I14: 6
A24: Tanda terima | E24: Sopir | H24: Teli kapal | K24: Teli gudang
A29: (…………………………………..)
A32: Catatan :

Sheet LAPORAN BLNAN
A7: LAPORAN KEGIATAN PERUSAHAAN BONGKAR MUAT
A9: Nama Perusahaan | C9: : | D9: PT. EMKA JAYA UTAMA
A10: Alamat Perusahaan | C10: : | D10: Mauponggo, Kel. Mauponggo, Kec. Mauponggo, Kab. Nagekeo
A11: Pelabuhan Bongkar Muat | C11: : | D11: Pelabuhan Kelas III Marapokot
A12: Nomor Induk Berusaha | C12: : | D12: 9120319120253
A13: Nomor Pokok Wajib Pajak | C13: : | D13: 90.611.700.7-923.000
A14: Laporan Untuk Bulan | C14: : | D14: Bulan Agustus 2023
A16: No | B16: Nama Kapal | D16: Bendera | E16: Ukuran DWT/GT / HPA | F16: Nama Agen Perusahaan Angkutan Laut | G16: Kegiatan B / M | K16: Asal Barang | L16: Tujuan | M16: Jenis | N16: Penunjukan PBM | O16: Ket
G17: Jumlah B/M | H17: Mulai Tanggal /Jam | I17: Selesai Tanggal /Jam | J17: Jumlah Buruh
A18: 1 | B18: =A18+1 -> 2 | D18: =B18+1 -> 3 | E18: =D18+1 -> 4 | F18: =E18+1 -> 5 | G18: =F18+1 -> 6 | H18: =G18+1 -> 7 | I18: =H18+1 -> 8 | J18: =I18+1 -> 9 | K18: =J18+1 -> 10 | L18: =K18+1 -> 11 | ... O18: =N18+1 -> 14
L27: ='TIME SHEET'!G33 -> Marapokot, 11 September 2023
L29: ='TIME SHEET'!G35 -> Perusahaan Bongkar muat dan Jasa Pengurusan Transportasi
L31: ='TIME SHEET'!G37 -> PT. EMKA JAYA UTAMA
L36: ='TIME SHEET'!G44 -> HILARIUS MBUSA
L37: ='TIME SHEET'!G45 -> Direktur
M49: Perusahaan Bongkar muat dan Jasa Pengurusan Transportasi

Sheet DKO PER 31 DES
A7: DATA KEGIATAN OPERASIONAL
A8: PT. EMKA JAYA UTAMA
A9: POSISI 31 DESEMBER 2022
A12: No. | B12: Bulan | C12: Unit Kapal Jumlah DWT/GT/HP | D12: Bongkar ( Ton/M3) | E12: Muat ( Ton/M3) | F12: Jumlah TKBM | G12: Lama Kegiatan | H12: Jumlah Jam Efektif | I12: Produktifitas B/M/Ton/Ship/Hr | J12: Ket
A13: 1 | B13: =A13+1 -> 2 | C13: =B13+1 -> 3 | D13: =C13+1 -> 4 | E13: =D13+1 -> 5 | F13: =E13+1 -> 6 | G13: =F13+1 -> 7 | H13: =G13+1 -> 8 | I13: =H13+1 -> 9 | J13: =I13+1 -> 10
G25: ='LAPORAN BLNAN'!L27 -> Marapokot, 11 September 2023
G27: ='LAPORAN BLNAN'!L29 -> Perusahaan Bongkar muat dan Jasa Pengurusan Transportasi
G29: ='LAPORAN BLNAN'!L31 -> PT. EMKA JAYA UTAMA
G36: ='LAPORAN BLNAN'!L36 -> HILARIUS MBUSA
G37: ='LAPORAN BLNAN'!L37 -> Direktur

Sheet Sheet1
A2: Nomor | B2: :
A3: Lampiran | B3: :
A4: Perihal | B4: :
A6: Sesuai dengan Peraturan Menteri Perhubungan Nomor 152 Tahun 2016 tentang Penyelenggaraan dan Pengusahaan Bongkar Muat Barang Dad Dan Ke Kapal, bersama ini kami PT.EMKA JAYA UTAMA (PBM/JPT) memberitahukan Laporan Bulanan kegiatan bongkar muat barang untuk bulan Agustus 2023. (Data tabel terlampir)
